{"name": "test_create_task_invalid_list", "status": "passed", "description": "Создание задачи с несуществующим list_id — должен вернуть ошибку", "steps": [{"name": "Пробуем создать задачу с неверным list_id", "status": "passed", "start": 1749677942514, "stop": 1749677944171}], "start": 1749677942513, "stop": 1749677944172, "uuid": "b5942dfb-727a-44f9-9927-ff6bd91586a5", "historyId": "f9ec46a87aece89d522f0adfeb7af775", "testCaseId": "f9ec46a87aece89d522f0adfeb7af775", "fullName": "tests.api.test_tasks.TestTasks#test_create_task_invalid_list", "labels": [{"name": "feature", "value": "Clickup API: Tasks"}, {"name": "parentSuite", "value": "tests.api"}, {"name": "suite", "value": "test_tasks"}, {"name": "subSuite", "value": "TestTasks"}, {"name": "host", "value": "A1"}, {"name": "thread", "value": "17376-MainThread"}, {"name": "framework", "value": "pytest"}, {"name": "language", "value": "cpython3"}, {"name": "package", "value": "tests.api.test_tasks"}]}