{"name": "test_create_task_invalid_list", "status": "passed", "description": "Создание задачи с несуществующим list_id — должен вернуть ошибку", "steps": [{"name": "Пробуем создать задачу с неверным list_id", "status": "passed", "start": 1749925210875, "stop": 1749925212365}], "start": 1749925210875, "stop": 1749925212365, "uuid": "2b6e72a4-1b0e-49dd-a5bd-8de2f85e1ecf", "historyId": "f9ec46a87aece89d522f0adfeb7af775", "testCaseId": "f9ec46a87aece89d522f0adfeb7af775", "fullName": "tests.api.test_tasks.TestTasks#test_create_task_invalid_list", "labels": [{"name": "feature", "value": "Clickup API: Tasks"}, {"name": "parentSuite", "value": "tests.api"}, {"name": "suite", "value": "test_tasks"}, {"name": "subSuite", "value": "TestTasks"}, {"name": "host", "value": "A1"}, {"name": "thread", "value": "37448-MainThread"}, {"name": "framework", "value": "pytest"}, {"name": "language", "value": "cpython3"}, {"name": "package", "value": "tests.api.test_tasks"}]}